Workbook
Name ___________GOR40: #REF!
Name ___________GOR50: #REF!
Name ___________GOR60: #REF!
Name ___________GOR80: #REF!
Name __________GOR40: #REF!
Name __________GOR50: #REF!
Name __________GOR60: #REF!
Name __________GOR80: #REF!
Name _________GOR40: #REF!
Name _________GOR50: #REF!
Name _________GOR60: #REF!
Name _________GOR80: #REF!
Name ________GOR40: #REF!
Name ________GOR50: #REF!
Name ________GOR60: #REF!
Name ________GOR80: #REF!
Name _______GOR40: #REF!
Name _______GOR50: #REF!
Name _______GOR60: #REF!
Name _______GOR80: #REF!
Name ______GOR40: #REF!
Name ______GOR50: #REF!
Name ______GOR60: #REF!
Name ______GOR80: #REF!
Name _____GOR40: #REF!
Name _____GOR50: #REF!
Name _____GOR60: #REF!
Name _____GOR80: #REF!
Name ____GOR40: #REF!
Name ____GOR50: #REF!
Name ____GOR60: #REF!
Name ____GOR80: #REF!
Name ___GOR40: #REF!
Name ___GOR50: #REF!
Name ___GOR60: #REF!
Name ___GOR80: #REF!
Name __GOR40: #REF!
Name __GOR50: #REF!
Name __GOR60: #REF!
Name __GOR80: #REF!
Name _GOR40: #REF!
Name _GOR50: #REF!
Name _GOR60: #REF!
Name _GOR80: #REF!
Name Aku: #REF!
Name Aku: #REF!
Name Aku: #REF!
Name Alat_Gr_buis_ppk: '[1]Gorong-Gorong Buis'!$J$23
Name Alat_Gr_buis_ppk: '[1]Gorong-Gorong Buis'!$J$23
Name Alat_Gr_buis_ppk: '[2]Gorong-Gorong Buis'!$J$23
Name Alat_Gr_buis_swadaya: '[1]Gorong-Gorong Buis'!$M$23
Name Alat_Gr_buis_swadaya: '[1]Gorong-Gorong Buis'!$M$23
Name Alat_Gr_buis_swadaya: '[2]Gorong-Gorong Buis'!$M$23
Name Alat_Gr_plat_ppk: #REF!
Name Alat_Gr_plat_ppk: #REF!
Name Alat_Gr_plat_ppk: #REF!
Name Alat_Gr_plat_ppk: #REF!
Name Alat_Gr_plat_swadaya: #REF!
Name Alat_Gr_plat_swadaya: #REF!
Name Alat_Gr_plat_swadaya: #REF!

Sheet RKPDESA 2026
A1: RANCANGAN RENCANA KERJA PEMERINTAH DESA (RKPDESA) | X1: BIDANG I | Y1: BIDANG II | Z1: BIDANG III | AA1: BIDANG IV | AB1: BIDANG V
A2: TAHUN ANGGARAN 2026 | X2: =Q9 -> 862664323 | Y2: =Q22 -> 1148231200 | Z2: =Q35 -> 102000000 | AA2: =Q47 -> 1000000 | AB2: =Q50 -> 128000000
A3: DESA PANDANLANDUNG KECAMATAN WAGIR KABUPATEN MALANG
A6: No | B6: Bidang | F6: Jenis Kegiatan | I6: Data Eksisting Tahun Berjalan | K6: Target Capaian Tahun 2023 | M6: Lokasi | N6: Volume dan Satuan | O6: Penerima Manfaat | P6: Waktu Pelaksanaan | Q6: Biaya dan Sumber Pembiayaan | S6: Pola Pelaksanaan (swakelola/ Kerjasama Antar Desa/ Kerjasama pihak Ketiga)
Q7: Jumlah (Rp) | R7: Sumber Biaya
A8: a | B8: b | F8: d | I8: f | K8: g | M8: h | N8: i | O8: j | P8: k | Q8: l | R8: m | S8: n | W8: JUMLAH PENGELUARAN PER SUMBER DANA | Y8: SISA DARI PAGU | Z8: PAGU
A9: 1 | B9: BIDANG PENYELENGGARAAN PEMERINTAHAN DESA | Q9: =SUM(Q10:Q21) -> 862664323
A10: BIDANG I | F10: 1 | G10: Penyediaan Penghasilan Tetap dan Tunjangan Kepala Desa | I10: 1 Org belum memenuhi pagu maksimal | K10: 1 org terpenuhi pagu | M10: Desa | N10: 1 OB | O10: 1 Org | P10: 12 Bulan | Q10: 11520000 | R10: ADD | S10: Swakelola | W10: ADD | X10: =Q10+Q11+Q13+Q14+Q15+Q46+Q36+Q37+Q38+Q39+Q41+102804000+Q42+Q43+Q45 -> 745232000 | Y10: =[7]PAGU!C5-'RKPDESA 2026'!X10 -> -59740000 | Z10: 694432000
F11: 2 | G11: Penyediaan Penghasilan Tetap dan Tunjangan Perangkat Desa | I11: 13 Org belum memenuhi pagu maksimal | K11: 13 org terpenuhi pagu | M11: Desa | N11: 13 OB | O11: 13 Org | P11: 12 Bulan | Q11: 339168000 | R11: ADD | S11: Swakelola | W11: DDS | X11: =Q16+Q23+Q24+Q51+Q25+Q26+Q27+X16+Q34+Q33+Q32+Q31+Q30+Q29+Q28 -> 1358198400 | Y11: =[7]PAGU!C6-'RKPDESA 2026'!X11 -> -167239400 | Z11: 1270999000
F12: 3 | G12: Penyediaan Operasional Pemerintah Desa (ATK, Honor PKPKD dan PPKD dll) | I12: Terpenuhi kebutuhan reguler | K12: Terpenuhi kebutuhan reguler | M12: Desa | N12: 1 Paket | O12: 14 Org | P12: 12 Bulan | Q12: =102804000+X16 -> 149042430 | R12: ADD, DDS | S12: Swakelola | W12: PBH | X12: =Q17+Q21+Q20+Q40+Q44 -> 132465123 | Y12: =[7]PAGU!C7-'RKPDESA 2026'!X12 -> 7435035 | Z12: 139513087
F13: 4 | G13: Penyediaan Tunjangan BPD | I13: 9 Org Terpenuhinya kesejahteraannya | K13: 9 Org Terpenuhinya kesejahteraannya | M13: Desa | N13: 9 OB | O13: 9 Org | P13: 12 Bulan | Q13: 58800000 | R13: ADD | S13: Swakelola | W13: PAD | X13: =Q18+Q19 -> 5000000 | Y13: =[7]PAGU!C8-'RKPDESA 2026'!X13 -> 0
F14: 5 | G14: Penyediaan Operasional BPD (rapat, ATK, Makan Minum, Pakaian Seragam, Listrik dll) | I14: Terpenuhinya Operasional BPD | K14: Terpenuhinya Operasional BPD | M14: Desa | N14: 1 Paket | O14: 9 Org | P14: 12 Bulan | Q14: 4000000 | R14: ADD | S14: Swakelola
F15: 6 | G15: Penyediaan Insentif/Operasional RT/RW | I15: 38 Org Terpenuhinya insentif RT | K15: 38 Org Terpenuhinya Kesejateraan RT | M15: Desa | N15: 38 OB | O15: 38 Org | P15: 12 Bulan | Q15: 143940000 | R15: ADD | S15: Swakelola | X15: =Q12+60000000 -> 209042430 | Y15: Ops Pemdes
F16: 7 | G16: Penyediaan Operasional Pemerintah Desa yang bersumber dari Dana Desa | I16: 1 Org Terpenuhinya pagu maskimal | K16: 1 Org Terpenuhinya pagu maskimal | M16: Desa | N16: 1 Paket | O16: 1 Ls | P16: 12 Bulan | Q16: 35728770 | R16: DDS | S16: Swakelola | X16: 46238430 | Y16: DDS
F17: 8 | G17: Sarana Prasana Kantor Desa | I17: Terpenuhinya kebutuhan Sarpras Kantor Desa | K17: Terpenuhi kebutuhan reguler | M17: Desa | N17: 1 Paket | O17: 1 Paket | P17: 12 Bulan | Q17: 90465123 | R17: PBH | S17: Swakelola
F18: 10 | G18: Penyelenggaraan Musdes | I18: Terlaksananya Musdes Reguler | K18: Terlaksananya Musdes Reguler | M18: Desa | N18: 1 Unit | O18: 14 Org | P18: Juni | Q18: 2500000 | R18: PAD | S18: Swakelola
F19: 11 | G19: Penyusunan RKPDes | I19: Tersusunnya RKPDesa | K19: Tersusunnya RKPDesa | M19: Kantor Desa | N19: 1 Paket | O19: 14 Org | P19: Juni | Q19: 2500000 | R19: PAD | S19: Swakelola
F20: 12 | G20: Penyusunan Kebijakan Desa | I20: Pembuatan Perdes | K20: Tersusunnya Perdes-perdes di Desa | M20: Kantor Desa | N20: 1 Unit | O20: 14 Org | P20: 12 Bulan | Q20: 6500000 | R20: PBH | S20: Swakelola
F21: 13 | G21: Pemungutan SPPT PBB | I21: Penyampaian SPPT PBB kepada WP | K21: Tersampaikannya SPPT kepada WP | M21: Desa | N21: 1 Paket | O21: 14 Org | P21: 12 Bulan | Q21: 18500000 | R21: PBH | S21: Swakelola
A22: 2 | B22: BIDANG PELAKSANAAN PEMBANGUNAN DESA | Q22: =SUM(Q23:Q34) -> 1148231200
A23: BIDANG II | F23: 1 | G23: Insentif Guru TPQ dan PAUD | I23: Guru Paud dan TPQ mendapat bantuan honor pengajar | K23: Guru Paud dan TPQ mendapat bantuan honor pengajar | M23: Desa | N23: 24 Lembaga | O23: 1 Ls | P23: Juni | Q23: 24000000 | R23: DDS | S23: Swakelola
F24: 2 | G24: Penyelenggaraan Posyandu | I24: Terselenggaranya Posyandu di Desa | K24: Pemberian Makanan Tambahan Balita dan Lansia | M24: Desa | N24: 12 POS | O24: 12 POS | P24: 12 Bulan | Q24: =POSYANDU!J51 -> 67284000 | R24: DDS | S24: Swakelola
F25: 3 | G25: Pembangunan Drainase RT 002 RW 001 | M25: RW 001 | N25: 1 Paket | O25: 1 Paket | P25: 12 Bulan | Q25: ='APBDES 2025'!E41 -> 84804800 | R25: DDS | S25: Swakelola | X25: Tim Pengelola Kegiatan Ta 2026 | Y25: . Oni Wibowo
F26: 4 | G26: Pembangunan Jalan Hotmix RT 011 RW 002 | M26: RW 002 | N26: 1 Paket | O26: 1 Paket | P26: Agustus | Q26: ='APBDES 2025'!E42 -> 56239000 | R26: DDS | S26: Swakelola | Y26: Hendri Kustomo
F27: 5 | G27: Pembangunan Drainase RT 015 RW 003 | M27: RW 003 | N27: 1 Paket | O27: 1 Paket | P27: 12 Bulan | Q27: ='APBDES 2025'!E43 -> 52002100 | R27: DDS | S27: Swakelola | Y27: Supardi
F28: 6 | G28: Pembangunan Drainase/Gorong-Gorong RT 017 RW 004 | M28: RW 004 | N28: 1 Paket | O28: 1 Paket | P28: 12 Bulan | Q28: ='APBDES 2025'!E44 -> 34674100 | R28: DDS | S28: Swakelola
F29: 7 | G29: Pembangunan Gorong-Gorong dan Pavingisasi | M29: RW 005 | N29: 1 Paket | O29: 1 Paket | P29: 12 Bulan | Q29: ='APBDES 2025'!E45 -> 54116400 | R29: DDS | S29: Swakelola
F30: 8 | G30: Pembangunan Drainase RT 026 RW 006 | M30: RW 006 | N30: 1 Paket | O30: 1 Paket | P30: 12 Bulan | Q30: ='APBDES 2025'!E46 -> 45571100 | R30: DDS | S30: Swakelola
F31: 10 | G31: Pembangunan Jalan Rabat RT 033 RW 007 | M31: RW 007 | N31: 1 Paket | O31: 1 Paket | P31: 12 Bulan | Q31: 89040200 | R31: DDS | S31: Swakelola
F32: 11 | G32: Pelaksanaan Kegiatan PKTD | M32: RT 12 | N32: 1 Paket | O32: 1 Paket | P32: 12 Bulan | Q32: 5000000 | R32: DDS | S32: Swakelola
F33: 12 | G33: Peningkatan Perekoniman Desa (30%) | M33: KOPDES | N33: 1Ls | O33: 1Ls | P33: 12 Bulan | Q33: 381299700 | R33: DDS | S33: Swakelola
F34: 13 | G34: Ketahanan Pangan 20% | M34: Ketapang | N34: 1Ls | O34: 1Ls | P34: 12 Bulan | Q34: 254199800 | R34: DDS | S34: Swakelola
A35: 3 | B35: BIDANG PEMBINAAN KEMASYARAKATAN | Q35: =SUM(Q36:Q46) -> 102000000
A36: BIDANG III | F36: 1 | G36: Pembinaan LPMD | I36: Penataan Kelembagaan LPMD | K36: Revitalisasi Tugas dan Fungsi LPMD | M36: 1 Lembaga | N36: 1 Paket | O36: 11 Org | P36: 12 Bulan | Q36: 3000000 | R36: ADD | S36: Swakelola
F37: 2 | G37: Pembinaan KIM | I37: Penataan Kelembagaan KIM | K37: Revitalisasi Tugas dan Fungsi KIM | M37: 1 Lembaga | N37: 1 Paket | O37: semua warga | P37: 12 Bulan | Q37: 5000000 | R37: ADD | S37: Swakelola
F38: 3 | G38: Pembinaan PB PANDAN | I38: Penataan Kelembagaan Olahraga | K38: Revitalisasi Tugas dan Fungsi Lembaga Olahraga | M38: 1 Lembaga | N38: 1 Paket | O38: semua warga | P38: 12 Bulan | Q38: 5000000 | R38: ADD | S38: Swakelola
F39: 4 | G39: Pembinaan SSB PANDAWA | I39: Penataan Kelembagaan Kesenian | K39: Revitalisasi Tugas dan Fungsi Lembaga Kesenian | M39: 1 Lembaga | N39: 1 Paket | O39: semua warga | P39: 12 Bulan | Q39: 12000000 | R39: ADD | S39: Swakelola
F40: 5 | G40: Peningkatan Kapasitas Linmas | I40: Perlengkapan Linmas Masih Belum memadai | K40: Memiliki perlengkapan dasar dalam menjalankan tugas | M40: 1 Lembaga | N40: 1 Paket | O40: 32 Org | P40: 1 Kali | Q40: 10000000 | R40: PBH | S40: Swakelola
F41: 6 | G41: Pembinaan Forum Anak Desa (FAD) | I41: Pelaksanaan PPA | K41: Refocusing DRPPA | M41: 1 Lembaga | N41: 1 Paket | O41: semua warga | P41: 12 Bulan | Q41: 5000000 | R41: ADD | S41: Swakelola
F42: 7 | G42: Pembinaan Swadeshi | I42: Siaga Kesehatan | K42: Peningkatan Kapasitas Relawan | M42: 2 Lembaga | N42: 1 Paket | O42: semua warga | P42: 12 Bulan | Q42: 5000000 | R42: ADD | S42: Swakelola
...

Sheet DU-RKPDESA 2026
A1: DAFTAR USULAN RENCANA KERJA PEMERINTAH DESA (DU-RKPDESA)
A2: TAHUN ANGGARAN 2026
A3: DESA PANDANLANDUNG KECAMATAN WAGIR KABUPATEN MALANG
A6: No | B6: Bidang | F6: Jenis Kegiatan | I6: Data Eksisting Tahun Berjalan | K6: Target Capaian Tahun 2023 | M6: Lokasi | N6: Volume dan Satuan | O6: Penerima Manfaat | P6: Waktu Pelaksanaan | Q6: Biaya dan Sumber Pembiayaan | S6: Pola Pelaksanaan (swakelola/ Kerjasama Antar Desa/ Kerjasama pihak Ketiga)
Q7: Jumlah (Rp) | R7: Sumber Biaya
A8: a | B8: b | G8: d | I8: f | K8: g | M8: h | N8: i | O8: j | P8: k | Q8: l | R8: m | S8: n
A9: 1 | B9: BIDANG PENYELENGGARAAN PEMERINTAHAN DESA | Q9: =SUM(Q10:Q10) -> 47400000
A10: BIDANG I | F10: 1 | G10: ='APBDES 2025'!D21 -> : Penyediaan Penghasilan Tetap dan Tunjangan Kepala Desa | K10: Peningkatan Kesejahteraan Kepala Desa | M10: Desa Pandanlandung | N10: 1 Org | P10: 12 Bulan | Q10: 47400000 | R10: APBDes
F11: 2 | G11: ='APBDES 2025'!D22 -> Penyediaan Penghasilan Tetap dan Tunjangan Perangkat Desa | K11: Peningkatan Kesejahteraan Perangkat Desa | M11: Desa Pandanlandung | N11: 11 Org | P11: 12 Bulan | Q11: 320400000 | R11: APBDes
F12: 3 | G12: ='APBDES 2025'!D23 -> BPJS Ketenaga kerjaan | K12: Peningkatan Kesejahteraan Perangkat Desa | M12: Desa Pandanlandung | N12: 17 Org | P12: 12 Bulan | Q12: 57222000 | R12: APBDes
F13: 4 | G13: ='APBDES 2025'!D24 -> Penyediaan Operasional Pemerintah Desa (ATK, Honor PKPKD, PPKD, dll) | K13: Peningkatan pelayanan pemerintah Desa | M13: Desa Pandanlandung | N13: 1 Paket | P13: 12 Bulan | Q13: 69399500 | R13: APBDes
F14: 5 | G14: ='APBDES 2025'!D25 -> Penyediaan Tunjangan BPD | K14: Peningkatan Kesejahteraan BPD | M14: Desa Pandanlandung | N14: 9 Org | P14: 12 Bulan | Q14: 30600000 | R14: APBDes
F15: 6 | G15: ='APBDES 2025'!D26 -> Penyediaan Operasional BPD (Rapat, ATK, Konsumsi, Pakaian Seragam, dll) | K15: Peningkatan pelayanan pemerintahan Desa | M15: Desa Pandanlandung | N15: 1 Paket | P15: 12 bulan | Q15: 5000000 | R15: APBDes
F16: 7 | G16: ='APBDES 2025'!D27 -> Penyediaan Insentif / Operasional RT/RW | K16: Peningkatan Pelayanan ke Masyrakat | M16: Desa Pandanlandung | N16: 45 Org | P16: 12 Bulan | Q16: 45000000 | R16: APBDes
F17: 8 | G17: ='APBDES 2025'!D28 -> Penyediaan Operasional Pemerintah Desa yang bersumber dari Dana Desa
F18: 9 | G18: ='APBDES 2025'!D29 -> Penyediaan Sarana (Aset Tetap) Perkantoran/Pemerintahan
F19: 10 | G19: ='APBDES 2025'!D30 -> Penyusunan Dokumen Perencanaan Desa dan Keuangan Desa (RPJMDes, RKPDes)
F20: 11 | G20: ='APBDES 2025'!D31 -> Penyelenggaan Musyawarah Perencanaan Desa APBDes (Reguler)
F21: 12 | G21: ='APBDES 2025'!D32 -> Penyelenggaraan Musyawarah Desa Lainnya (Musdus, Rembug Desa Non Reguler)
F22: 13 | G22: ='APBDES 2025'!D33 -> Penyusunan Kebijakan Desa (Peraturan Desa, Peraturan Kepala Desa, selain RKPDes dan APBDes)
F23: 14 | G23: ='APBDES 2025'!D34 -> Administrasi Pajak Bumi dan Bangunan (PBB)
F24: 15 | G24: ='APBDES 2025'!D35 -> Penyediaan Operasional Pemerintah Desa (Pajak)
F25: 16 | G25: ='APBDES 2025'!D36 -> Penyelenggaraan Pemilihan Kepala Desa
F26: 17
A27: 2 | B27: BIDANG PELAKSANAAN PEMBANGUNAN DESA | Q27: =SUM(Q28:Q78) -> 0
A28: BIDANG II | F28: 1 | G28: ='APBDES 2025'!D38 -> Penyelanggaraan PAUD.TPA/TKA/TPQ/Madrasah Non Formal Milik Desa (Honor, Pakaian, dll) | R28: APBD | S28: Dinas Terkait
F29: 2 | G29: ='APBDES 2025'!D39 -> Penyelenggaraan Posyandu (PMT, Kelas Ibu Hamil, Lansia, Insentif) | R29: APBD | S29: Dinas Terkait
F30: 3 | G30: ='APBDES 2025'!D40 -> Sarana Prasarana Pos Kesehatan Desa | R30: APBD | S30: Dinas Terkait
F31: 4 | G31: ='APBDES 2025'!D41 -> Pembangunan Drainase RT 002 RW 001
F32: 5 | G32: ='APBDES 2025'!D42 -> Pembangunan Jalan Hotmix RT 011 RW 002
F33: 6 | G33: ='APBDES 2025'!D43 -> Pembangunan Drainase RT 015 RW 003
F34: 7 | G34: ='APBDES 2025'!D44 -> Pembangunan Drainase/Gorong-Gorong RT 017 RW 004
F35: 8 | G35: ='APBDES 2025'!D45 -> Pembangunan Gorong-Gorong dan Pavingisasi gg Sekolahan RW 005
F36: 9 | G36: ='APBDES 2025'!D46 -> Pembangunan Drainase RT 026 RW 006 | R36: APBD | S36: Dinas Terkait
F37: 10 | G37: ='APBDES 2025'!D47 -> Pelaksanaan Kegiatan PKTD | R37: APBD | S37: Dinas Terkait
F38: 11 | G38: ='APBDES 2025'!D48 -> Pembangunan Jalan Paving RT 033 RW 007 | R38: APBD | S38: Dinas Terkait
G39: •Gorong-gorong RT 9-11 Beton Buis dm 40
G40: •Paving RT.6 , RT. 8, RT.9
G41: •Talang Cor (arah Sungai RT.10)
G42: •Melanjutkan pekerjaan Bina marga RT 6
...

Sheet PENDAPATAN DESA
A1: RINCIAN ANGGARAN PENDAPATAN
A2: DESA PANDANLANDUNG
A3: TAHUN ANGGARAN 2026
A6: KODE | B6: URAIAN | E6: ANGGARAN (Rp.) | F6: SUMBER DANA
A7: 1 | B7: 2 | E7: 3 | F7: 4
A8: 4. | B8: PENDAPATAN
A9: 4.1. | C9: Pendapatan Asli Desa | E9: =E10 -> 0
C10: 1 | D10: Hasil Pengelolaan TKD | E10: 0 | F10: PAD
A11: 4.2. | C11: Pendapatan Transfer | E11: =SUM(E12:E14) -> 2104944087
C12: 1 | D12: Alokasi Dana Desa | E12: 694432000 | F12: ADD
C13: 2 | D13: Dana Desa | E13: 1270999000 | F13: DDS
C14: 3 | D14: Pendapatan Bagi Hasil Pajak dan Retribusi | E14: 139513087 | F14: PBH
A15: 4.3. | C15: Pendapatan Lain-Lain | E15: =SUM(E16:E17) -> 7214124
C16: 1 | D16: Bagi Hasil Kerjasama Antar Desa | E16: 5000000 | F16: DLL
C17: 2 | D17: Bunga Bank | E17: 2214124 | F17: DLL
A18: JUMLAH PENDAPATAN | E18: =E15+E11+E9 -> 2112158211

Sheet PENERIMAAN PEMBIAYAAN
A1: PEMERINTAH DESA PANDANLANDUNG
A2: RINCIAN PENERIMAAN PEMBIAYAAN DESA | L2: PROYEKSI SILPA APBDES 2025
A3: TAHUN ANGGARAN 2026
A6: KODE | B6: U R A I A N | G6: RINCIAN
G7: VOLUME | I7: HARGA SATUAN | J7: JUMLAH (Rp)
A8: 1 | B8: 2 | G8: 3 | I8: 4 | J8: 5
A9: 6 | B9: PEMBIYAAN | J9: =J10 -> 197166973
A10: 6.1. | B10: Penerimaan Pembiayaan | J10: =J11 -> 197166973
A11: 6.1.1. | C11: Silpa Tahun Sebelumnya | J11: =SUM(J12:J15) -> 197166973 | L11: SISA ANGGARAN BELUM TERALOKASI
C12: 01 | D12: Silpa Alokasi Dana Desa | E12: ADD | G12: 1 | H12: LS | I12: 141150958 | J12: =I12*G12 -> 141150958 | L12: =J12-N2 -> 141150958
C13: 02 | D13: Silpa Dana Desa | E13: DDS | G13: 1 | H13: LS | I13: 500000 | J13: =I13*G13 -> 500000
C14: 03 | D14: Silpa Pajak Bagi Hasil dan Retribusi Daerah | E14: PBH | G14: 1 | H14: LS | I14: 37755495 | J14: =I14*G14 -> 37755495
C15: 04 | D15: Silpa Pendapatan lain-lain | E15: DLL | G15: 1 | H15: LS | I15: 17760520 | J15: =I15*G15 -> 17760520
B16: JUMLAH (Rp) | J16: =J9 -> 197166973
G18: Pandanlandung, 29 November 2025
A19: Pj. Kepala Desa Pandanlandung | G19: Sekretaris Desa Pandanlandung
A23: HARI SULISTIONO, S.AP | G23: ACHMAD BAGUS SADEWA

Sheet PENGELUARAN PEMBIAYAAN
A1: PEMERINTAH DESA PANDANLANDUNG
A2: RINCIAN PENGELUARAN PEMBIAYAAN DESA
A3: TAHUN ANGGARAN 2024
A6: KODE | B6: U R A I A N | G6: RINCIAN
G7: VOLUME | I7: HARGA SATUAN | J7: JUMLAH (Rp)
A8: 1 | B8: 2 | G8: 3 | I8: 4 | J8: 5
A9: 6 | B9: PEMBIYAAN | J9: =J10 -> 254500000
A10: 6.1. | B10: Pengeluaran Pembiayaan | J10: =J11 -> 254500000
A11: 6.1.1. | C11: Silpa Tahun Sebelumnya | J11: =SUM(J12:J12) -> 254500000
C12: 01 | D12: Penyertaan Modal BUMDes | E12: DDS | G12: 1 | H12: Kl | I12: 254500000 | J12: =I12*G12 -> 254500000
B13: JUMLAH (Rp) | J13: =J9 -> 254500000
G15: Pandanlandung, 29 November 2025
A16: Pj. Kepala Desa Pandanlandung | G16: Sekretaris Desa Pandanlandung
A20: HARI SULISTIONO, S.AP | G20: ACHMAD BAGUS SADEWA

Sheet KONTROL ANGGARAN SUMBER DANA
A1: FORM KONTROL ANGGARAN PER SUMBER DANA
A2: DESA PANDANLANDUNG
A3: TAHUN ANGGARAN 2026
A6: KODE | B6: URAIAN | E6: ANGGARAN (Rp.) | F6: TERPAKAI | G6: SISA | H6: SUMBER DANA
A7: 1 | B7: 2 | E7: 3 | F7: 4 | G7: 5 | H7: 6
A8: 4. | B8: PENDAPATAN
A9: 4.1. | C9: Pendapatan Asli Desa | E9: =E10 -> 2000000 | G9: =G10 -> 0
C10: 1 | D10: Hasil Pengelolaan TKD | E10: 2000000 | F10: =2000000 -> 2000000 | G10: =E10-F10 -> 0 | H10: PAD
A11: 4.2. | C11: Pendapatan Transfer | E11: =SUM(E12:E14) -> 2104944087 | G11: =SUM(G12:G14) -> 143562171
C12: 1 | D12: Alokasi Dana Desa | E12: ='PENDAPATAN DESA'!E12 -> 694432000 | F12: =KADES!K3+PERANGKAT!M3+BPJS!M3+'OPS PEMDES'!M3+BPD!M3+'OPS BPD'!M3+'RT RW'!M3+'SARPRAS KANTOR DESA'!M5+'OPS LPMD'!M4+'OPS PKK'!M4 -> 712241216 | G12: =E12-F12 -> -17809216 | H12: ADD
C13: 2 | D13: Dana Desa | E13: ='PENDAPATAN DESA'!E13 -> 1270999000 | F13: ='OPS PEMDES'!M4+'OPS PEMDES 3%'!M4+'SUN RKP'!M4+'Sun APBDes'!M4+'PAUD TPQ'!J18+'SARPRAS POSYANDU'!M2+POSYANDU!M3+'RT 02 RW 01'!J3+'RW 2'!O2+'RT 15 RW 3'!N3+'RW 04.'!T4+'RW 5'!T3+'RW 06'!I2+'RW 07'!Q2+PKTD!U4+'OPS KIM'!M3+'OPS KESENIAN'!M3+'BLT DD'!M3+'PENGELUARAN PEMBIAYAAN'!J13+'OPS RW'!M5+'OPS PB. PANDANLANDUNG'!M3+KDMP!M3 -> 1101995700 | G13: =E13-F13 -> 169003300 | H13: DDS
C14: 3 | D14: Pendapatan Bagi Hasil Pajak dan Retribusi | E14: ='PENDAPATAN DESA'!E14 -> 139513087 | F14: ='SARPRAS KANTOR DESA'!M3 -> 147145000 | G14: =E14-F14 -> -7631913 | H14: PBH
A15: 4.3. | C15: Pendapatan Lain-Lain | E15: =SUM(E16:E16) -> 5000000 | G15: =G16 -> 5000000
C16: 1 | D16: Bagi Hasil Kerjasama Antar Desa | E16: 5000000 | G16: =E16-F16 -> 5000000 | H16: DLL
C17: 2 | D17: ='PENDAPATAN DESA'!D17 -> Bunga Bank | E17: ='PENDAPATAN DESA'!E17 -> 2214124
A18: 6. | B18: PENERIMAAN PEMBIAYAAN | J18: =254500000-213653300 -> 40846700
A19: 6.1 | C19: Silpa Tahun Sebelumnya | E19: =SUM(E20:E23) -> 197166973 | G19: =SUM(G20:G22) -> 179406453
C20: 1 | D20: Silpa Alokasi Dana Desa | E20: ='PENERIMAAN PEMBIAYAAN'!I12 -> 141150958 | G20: =E20-F20 -> 141150958 | H20: s.ADD
C21: 2 | D21: Silpa Dana Desa | E21: ='PENERIMAAN PEMBIAYAAN'!I13 -> 500000 | G21: =E21-F21 -> 500000 | H21: s.DDS
C22: 3 | D22: Silpa Pajak Bagi Hasil dan Retribusi Daerah | E22: ='PENERIMAAN PEMBIAYAAN'!I14 -> 37755495 | G22: =E22-F22 -> 37755495 | H22: s.PBH
C23: 4 | D23: Silpa Pendapatan lain-lain | E23: ='PENERIMAAN PEMBIAYAAN'!I15 -> 17760520 | G23: =E23-F23 -> 17760520 | H23: s.DLL
A24: JUMLAH ANGGARAN DIKELOLA | E24: =E15+E11+E9+E19 -> 2309111060 | F24: =F15+F11+F9 -> 0 | G24: =G15+G11+G9+G19 -> 327968624

Sheet BELANJA PER BIDANG
A1: ANGGARAN PENDAPATAN DAN BELANJA DESA (APBDESA)
A2: DESA PANDANLANDUNG
A3: TAHUN ANGGARAN 2024
A6: KODE | B6: URAIAN | E6: ANGGARAN (Rp.) | F6: SUMBER DANA
A7: 1 | B7: 2 | E7: 3 | F7: 4
A8: 4. | B8: PENDAPATAN
A9: 4.1. | C9: Pendapatan Asli Desa | E9: =E10 -> 2000000
C10: 1 | D10: Hasil Pengelolaan TKD | E10: 2000000 | F10: PAD
A11: 4.2. | C11: Pendapatan Transfer | E11: =SUM(E12:E14) -> 2104944087
C12: 1 | D12: Alokasi Dana Desa | E12: ='PENDAPATAN DESA'!E12 -> 694432000 | F12: ADD
C13: 2 | D13: Dana Desa | E13: ='PENDAPATAN DESA'!E13 -> 1270999000 | F13: DDS
C14: 3 | D14: Pendapatan Bagi Hasil Pajak dan Retribusi | E14: ='PENDAPATAN DESA'!E14 -> 139513087 | F14: PBH
A15: 4.3. | C15: Pendapatan Lain-Lain | E15: =SUM(E16:E16) -> 5000000
C16: 1 | D16: Bagi Hasil Kerjasama Antar Desa | E16: ='PENDAPATAN DESA'!E16 -> 5000000 | F16: DLL
C17: 2 | D17: ='PENDAPATAN DESA'!D17 -> Bunga Bank | E17: ='PENDAPATAN DESA'!E17 -> 2214124
A18: JUMLAH PENDAPATAN | E18: =E15+E11+E9 -> 2111944087
A19: 5. | B19: BELANJA
A20: 5.01. | C20: BIDANG PENYELENGGARAAN PEMERINTAHAN DESA | E20: ='APBDES 2025'!E20 -> 1018084216
C21: 1 | D21: =KADES!B6 -> : Penyediaan Penghasilan Tetap dan Tunjangan Kepala Desa | E21: =KADES!H19 -> 59520000 | F21: ADD
C22: 2 | D22: =PERANGKAT!D6 -> Penyediaan Penghasilan Tetap dan Tunjangan Perangkat Desa | E22: =PERANGKAT!J26 -> 339168000 | F22: ADD
C23: 3 | D23: Penyediaan Operasional Pemerintah Desa (ATK, Honor PKPKD, PPKD, dll) | E23: ='OPS PEMDES'!J82 -> 164090000 | F23: ADD, DDS
C24: 4 | D24: =BPD!D6 -> Penyediaan Tunjangan BPD | E24: =BPD!J20 -> 58800000 | F24: ADD
C25: 5 | D25: Penyediaan Operasional BPD (Rapat, ATK, Konsumsi, Pakaian Seragam, dll) | E25: ='OPS BPD'!J17 -> 4000000 | F25: ADD
C26: 6 | D26: Penyediaan Insentif / Operasional RT/RW | E26: ='RT RW'!J18 -> 143940000 | F26: ADD
C27: 7 | D27: Penyediaan Operasional Pemerintah Desa yang bersumber dari Dana Desa | E27: ='OPS PEMDES 3%'!J28 -> 38129000 | F27: DDS
C28: 8 | D28: Penyediaan Sarana (Aset Tetap) Perkantoran/Pemerintahan | E28: ='SARPRAS KANTOR DESA'!J43 -> 175195000 | F28: PBH
C29: 9 | D29: Pengembangan Sistem Informasi Desa (SDGs) | E29: =#REF! -> #REF! | F29: DDS
C30: 10 | D30: Penyusunan Dokumen Perencanaan Desa dan Keuangan Desa (RPJMDes, RKPDes) | E30: ='SUN RKP'!J33 -> 2705000 | F30: DDS
C31: 11 | D31: Penyelenggaraan Musyawarah Desa Lainnya (Musdus, Rembug Desa Non Reguler) | E31: =NONREGULER!J24 -> 2000000 | F31: PAD
C32: 12 | D32: Penyusunan Kebijakan Desa (Peraturan Desa, Peraturan Kepala Desa, selain RKPDes dan APBDes) | E32: ='SUN KEBIJAKAN DESA'!J21 -> 500000 | F32: PBH
C33: 13 | D33: Administrasi Pajak Bumi dan Bangunan (PBB) | E33: ='SPPT PBB'!J18 -> 20330000 | F33: PBH
A34: 5.02. | C34: BIDANG PELAKSANAAN PEMBANGUNAN DESA | E34: ='APBDES 2025'!E37 -> 423691500
C35: 1 | D35: ='PAUD TPQ'!D6 -> Penyelanggaraan PAUD.TPA/TKA/TPQ/Madrasah Non Formal Milik Desa (Honor, Pakaian, dll) | E35: ='PAUD TPQ'!J18 -> 24000000 | F35: DDS
C36: 2 | D36: =POSYANDU!D6 -> Penyelenggaraan Posyandu (PMT, Kelas Ibu Hamil, Lansia, Insentif) | E36: =POSYANDU!J51 -> 67284000 | F36: DDS
C37: 3 | D37: =#REF! -> #REF! | E37: =#REF! -> #REF! | F37: DDS
C38: 4 | D38: =#REF! -> #REF! | E38: =#REF! -> #REF! | F38: DDS
C39: 5 | D39: =#REF! -> #REF! | E39: =#REF! -> #REF! | F39: DDS
A40: 5.03. | C40: BIDANG PEMBINAAN KEMASYARAKATAN | E40: ='APBDES 2025'!E49 -> 43040000
C41: 1 | D41: ='OPS LPMD'!D6 -> Pembinaan Kelembagaan LPMD | E41: ='OPS LPMD'!J19 -> 3000000 | F41: ADD
C42: 2 | D42: ='OPS KIM'!D6 -> Pembinaan Kelembagaan Kelompok Informasi Masyarakat (KIM) | E42: ='OPS KIM'!J18 -> 5000000 | F42: DDS
...

Sheet APBDES 2025
A1: ANGGARAN PENDAPATAN DAN BELANJA DESA (APBDESA)
A2: DESA PANDANLANDUNG
A3: TAHUN ANGGARAN 2026
A6: KODE | B6: URAIAN | E6: ANGGARAN (Rp.) | F6: SUMBER DANA
A7: 1 | B7: 2 | E7: 3 | F7: 4
A8: 4. | B8: PENDAPATAN
A9: 4.1. | C9: Pendapatan Asli Desa | E9: =E10 -> 0
C10: 1 | D10: Hasil Pengelolaan TKD | E10: ='PENDAPATAN DESA'!E10 -> 0 | F10: PAD
A11: 4.2. | C11: Pendapatan Transfer | E11: =SUM(E12:E14) -> 2104944087
C12: 1 | D12: Alokasi Dana Desa | E12: ='PENDAPATAN DESA'!E12 -> 694432000 | F12: ADD
C13: 2 | D13: Dana Desa | E13: ='PENDAPATAN DESA'!E13 -> 1270999000 | F13: DDS
C14: 3 | D14: Pendapatan Bagi Hasil Pajak dan Retribusi | E14: ='PENDAPATAN DESA'!E14 -> 139513087 | F14: PBH
A15: 4.3. | C15: Pendapatan Lain-Lain | E15: =SUM(E16:E16) -> 5000000
C16: 1 | D16: Bagi Hasil Kerjasama Antar Desa | E16: ='PENDAPATAN DESA'!E16 -> 5000000 | F16: DLL
C17: 2 | D17: ='BELANJA PER BIDANG'!D17 -> Bunga Bank | E17: ='BELANJA PER BIDANG'!E17 -> 2214124 | F17: DLL
A18: JUMLAH PENDAPATAN | E18: =E15+E11+E9 -> 2109944087
A19: 5. | B19: BELANJA
A20: 5.01. | C20: BIDANG PENYELENGGARAAN PEMERINTAHAN DESA | E20: =SUM(E21:E36) -> 1018084216
C21: 1 | D21: =KADES!B6 -> : Penyediaan Penghasilan Tetap dan Tunjangan Kepala Desa | E21: =KADES!H19 -> 59520000 | F21: ADD
C22: 2 | D22: =PERANGKAT!D6 -> Penyediaan Penghasilan Tetap dan Tunjangan Perangkat Desa | E22: =PERANGKAT!J26 -> 339168000 | F22: ADD
C23: 3 | D23: BPJS Ketenaga kerjaan | E23: =BPJS!M3 -> 2763216 | F23: ADD
C24: 4 | D24: Penyediaan Operasional Pemerintah Desa (ATK, Honor PKPKD, PPKD, dll) | E24: ='OPS PEMDES'!J82 -> 164090000 | F24: ADD, DDS
C25: 5 | D25: =BPD!D6 -> Penyediaan Tunjangan BPD | E25: =BPD!J20 -> 58800000 | F25: ADD
C26: 6 | D26: Penyediaan Operasional BPD (Rapat, ATK, Konsumsi, Pakaian Seragam, dll) | E26: ='OPS BPD'!J17 -> 4000000 | F26: ADD
C27: 7 | D27: Penyediaan Insentif / Operasional RT/RW | E27: ='RT RW'!J18 -> 143940000 | F27: ADD
C28: 8 | D28: Penyediaan Operasional Pemerintah Desa yang bersumber dari Dana Desa | E28: ='OPS PEMDES 3%'!J28 -> 38129000 | F28: DDS
C29: 9 | D29: Penyediaan Sarana (Aset Tetap) Perkantoran/Pemerintahan | E29: ='SARPRAS KANTOR DESA'!J43 -> 175195000 | F29: PBH
C30: 10 | D30: Penyusunan Dokumen Perencanaan Desa dan Keuangan Desa (RPJMDes, RKPDes) | E30: ='SUN RKP'!J33 -> 2705000 | F30: DDS
C31: 11 | D31: Penyelenggaan Musyawarah Perencanaan Desa APBDes (Reguler) | E31: ='Sun APBDes'!M4 -> 4430000 | F31: DDS
C32: 12 | D32: Penyelenggaraan Musyawarah Desa Lainnya (Musdus, Rembug Desa Non Reguler) | E32: =NONREGULER!J24 -> 2000000 | F32: PAD
C33: 13 | D33: Penyusunan Kebijakan Desa (Peraturan Desa, Peraturan Kepala Desa, selain RKPDes dan APBDes) | E33: ='SUN KEBIJAKAN DESA'!J21 -> 500000 | F33: PBH, DLL
C34: 14 | D34: Administrasi Pajak Bumi dan Bangunan (PBB) | E34: ='SPPT PBB'!J18 -> 20330000 | F34: PBH
C35: 15 | D35: Penyediaan Operasional Pemerintah Desa (Pajak) | E35: ='OPERASIONAL PAJAK'!M3 -> 2514000 | F35: DLL
C36: 16 | D36: Penyelenggaraan Pemilihan Kepala Desa | F36: SAD
A37: 5.02. | C37: BIDANG PELAKSANAAN PEMBANGUNAN DESA | E37: =SUM(E38:E47) -> 423691500
C38: 1 | D38: ='PAUD TPQ'!D6 -> Penyelanggaraan PAUD.TPA/TKA/TPQ/Madrasah Non Formal Milik Desa (Honor, Pakaian, dll) | E38: ='PAUD TPQ'!J18 -> 24000000 | F38: DDS
C39: 2 | D39: =POSYANDU!D6 -> Penyelenggaraan Posyandu (PMT, Kelas Ibu Hamil, Lansia, Insentif) | E39: =POSYANDU!J51 -> 67284000 | F39: DDS
D40: Sarana Prasarana Pos Kesehatan Desa
C41: 3 | D41: Pembangunan Drainase RT 002 RW 001 | E41: ='RT 02 RW 01'!J3 -> 84804800 | F41: DDS
C42: 4 | D42: Pembangunan Jalan Hotmix RT 011 RW 002 | E42: ='RW 2'!O2 -> 56239000 | F42: DDS
...

Sheet KADES
A1: RENCANA ANGGARAN BIAYA (RAB)
A2: PEMERINTAH DESA PANDANLANDUNG | J2: Check Sum:
A3: TAHUN ANGGARAN 2026 | J3: ADD | K3: =H19 -> 59520000
A5: Bidang | B5: : PENYELENGGARAAN PEMERINTAHAN DESA
A6: Kegiatan | B6: : Penyediaan Penghasilan Tetap dan Tunjangan Kepala Desa
A7: Waktu | B7: : 12 Bulan
A8: Output | B8: : Pembayaran Siltap dan Tunjangan Kepala Desa
A10: KODE | B10: U R A I A N | E10: RINCIAN
E11: VOLUME | G11: HARGA SATUAN | H11: JUMLAH (Rp)
A12: 1 | B12: 2 | E12: 3 | G12: 4 | H12: 5
A13: 5 | B13: BELANJA | H13: =H14 -> 59520000 | J13: Dasar Hukum: Peraturan Bupati Malang Nomor 202 Tahun 2022 tentang Pendapatan Kades, Perangkat Desa, Tunjangan BPD, dan Insentif Ketua RT dan Ketua RW (Pasal 4 dan 5)
A14: 5.1.1. | B14: Penghasilan Tetap dan Tunjangan Kepala Desa | H14: =H17+H15 -> 59520000
A15: 5.1.1.01. | B15: Penghasilan Tetap Kepala Desa | H15: =H16 -> 48000000
B16: 01. Kepala Desa | C16: ADD | E16: 12 | F16: OB | G16: 4000000 | H16: =G16*E16 -> 48000000
A17: 5.1.1.02. | B17: Tunjangan Kepala Desa | H17: =H18 -> 11520000
B18: 01. Kepala Desa | C18: ADD | E18: 12 | F18: OB | G18: 960000 | H18: =G18*E18 -> 11520000
B19: JUMLAH (Rp) | H19: =H13 -> 59520000
E21: Pandanlandung, 29 November 2025
A22: Pj. Kepala Desa Pandanlandung | E22: Pelaksana Kegiatan
A26: HARI SULISTIONO, S.AP | E26: NOVIA RAHAYU

Sheet PERANGKAT
A1: RENCANA ANGGARAN BIAYA (RAB)
A2: PEMERINTAH DESA PANDANLANDUNG | L2: Check Sum:
A3: TAHUN ANGGARAN 2026 | L3: ADD | M3: =J21+J15 -> 339168000
A5: Bidang | C5: : | D5: PENYELENGGARAAN PEMERINTAHAN DESA
A6: Kegiatan | C6: : | D6: Penyediaan Penghasilan Tetap dan Tunjangan Perangkat Desa
A7: Waktu | C7: : | D7: 12 Bulan
A8: Output | C8: : | D8: Pembayaran Siltap dan Tunjangan Perangkat Desa
A10: KODE | B10: U R A I A N | G10: RINCIAN
G11: VOLUME | I11: HARGA SATUAN | J11: JUMLAH (Rp)
A12: 1 | B12: 2 | G12: 3 | I12: 4 | J12: 5
A13: 5 | B13: BELANJA | J13: =J14+J20 -> 339168000
A14: 5.1.1. | B14: Penghasilan Tetap dan Tunjangan Perangkat Desa | J14: =J15 -> 300000000
A15: 5.1.1.01. | C15: Penghasilan Tetap Perangkat Desa | J15: =SUM(J16:J19) -> 300000000 | L15: Dasar Hukum: Peraturan Bupati Malang Nomor 202 Tahun 2022 tentang Pendapatan Kades, Perangkat Desa, Tunjangan BPD, dan Insentif Ketua RT dan Ketua RW (Pasal 4 dan 5)
C16: 01 | D16: Sekretaris Desa | E16: ADD | G16: 12 | H16: OB | I16: 2500000 | J16: =I16*G16 -> 30000000
C17: 02 | D17: Kepala Urusan | E17: ADD | G17: 36 | H17: OB | I17: 2250000 | J17: =I17*G17 -> 81000000
C18: 03 | D18: Kepala Seksi | E18: ADD | G18: 36 | H18: OB | I18: 2250000 | J18: =I18*G18 -> 81000000
C19: 04 | D19: Kepala Dusun | E19: ADD | G19: 48 | H19: OB | I19: 2250000 | J19: =I19*G19 -> 108000000
A20: 5.1.1. | B20: Penghasilan Tetap dan Tunjangan Perangkat Desa | J20: =J21 -> 39168000
A21: 5.1.1.02. | C21: Tunjangan Perangkat Desa | J21: =SUM(J22:J25) -> 39168000
C22: 01 | D22: Sekretaris Desa | E22: ADD | G22: 12 | H22: OB | I22: 384000 | J22: =I22*G22 -> 4608000
C23: 02 | D23: Kepala Urusan | E23: ADD | G23: 36 | H23: OB | I23: 288000 | J23: =I23*G23 -> 10368000
C24: 03 | D24: Kepala Seksi | E24: ADD | G24: 36 | H24: OB | I24: 288000 | J24: =I24*G24 -> 10368000
C25: 04 | D25: Kepala Dusun | E25: ADD | G25: 48 | H25: OB | I25: 288000 | J25: =I25*G25 -> 13824000
B26: JUMLAH (Rp) | J26: =J13 -> 339168000
G28: Pandanlandung, 29 November 2025
A29: Pj. Kepala Desa Pandanlandung | G29: Pelaksana Kegiatan
A33: HARI SULISTIONO, S.AP | G33: NOVIA RAHAYU

Sheet BPJS
A1: RENCANA ANGGARAN BIAYA (RAB)
A2: PEMERINTAH DESA PANDANLANDUNG | L2: Check Sum:
A3: TAHUN ANGGARAN 2026 | L3: ADD | M3: =J13 -> 2763216
A5: Bidang | C5: : | D5: PENYELENGGARAAN PEMERINTAHAN DESA
A6: Kegiatan | C6: : | D6: Penyediaan Penghasilan Tetap dan Tunjangan Perangkat Desa
A7: Waktu | C7: : | D7: 12 Bulan
A8: Output | C8: : | D8: Pembayaran Siltap dan Tunjangan Perangkat Desa
A10: KODE | B10: U R A I A N | G10: RINCIAN
G11: VOLUME | I11: HARGA SATUAN | J11: JUMLAH (Rp)
A12: 1 | B12: 2 | G12: 3 | I12: 4 | J12: 5
A13: 5 | B13: BELANJA | J13: =J14 -> 2763216
A14: 5.1.1. | B14: Pembayaran Iuran BPJS Ketenaga Kerjaan | J14: =J15+J18 -> 2763216
A15: 5.1.1.01. | C15: Pembayaran Iuran BPJS Ketenaga Kerjaan Kepala Desa | J15: =SUM(J16:J17) -> 230268
C16: 01 | D16: Jaminan Kematian | E16: ADD | G16: 12 | H16: OB | I16: 10661 | J16: =I16*G16 -> 127932
C17: 02 | D17: Jaminan Kecelakaan Kerja | E17: ADD | G17: 12 | H17: OB | I17: 8528 | J17: =I17*G17 -> 102336
C18: Pembayaran Iuran BPJS Ketenagakerjaan Perangkat Desa | J18: =SUM(J19:J20) -> 2532948
C19: 01 | D19: Jaminan Kematian | E19: ADD | G19: 132 | H19: OB | I19: 10661 | J19: =I19*G19 -> 1407252
C20: 02 | D20: Jaminan Kecelakaan Kerja | E20: ADD | G20: 132 | H20: OB | I20: 8528 | J20: =I20*G20 -> 1125696
B21: JUMLAH (Rp) | J21: =J13 -> 2763216
G23: Pandanlandung, 29 November 2025
A24: Pj. Kepala Desa Pandanlandung | G24: Pelaksana Kegiatan
A28: HARI SULISTIONO, S.AP | G28: NOVIA RAHAYU

Sheet OPS PEMDES
A1: RENCANA ANGGARAN BIAYA (RAB)
A2: PEMERINTAH DESA PANDANLANDUNG | L2: Check Sum:
A3: TAHUN ANGGARAN 2026 | L3: ADD | M3: =J60+J66+J75 -> 63000000 | P3: =M3+M5 -> 119290000
L4: DDS | M4: =J77+J70 -> 44800000 | P4: =P3+M4 -> 164090000
A5: Bidang | C5: : | D5: PENYELENGGARAAN PEMERINTAHAN DESA | L5: SILPA ADD | M5: =J15+J51+J57 -> 56290000
A6: Kegiatan | C6: : | D6: Penyediaan Operasional Pemerintah Desa (ATK, Honor PKPKD, PPKD, dll)
A7: Waktu | C7: : | D7: 12 Bulan | N7: =M3+M5+M4 -> 164090000
A8: Output | C8: : | D8: Penyediaan Operasional Pemerintah Desa
A10: KODE | B10: U R A I A N | G10: RINCIAN
G11: VOLUME | I11: HARGA SATUAN | J11: JUMLAH (Rp)
A12: 1 | B12: 2 | G12: 3 | I12: 4 | J12: 5
A13: 5 | B13: BELANJA | J13: =J14+J57+J60+J66+J74+J70 -> 164090000
A14: 5.2.1. | B14: Belanja Barang dan Perlengkapan | J14: =J15+J52 -> 41290000
A15: 5.1.1.01. | C15: Belanja Alat Tulis Kantor dan Benda Pos | J15: =SUM(J16:J50) -> 30790000
C16: 01 | D16: Kertas HVS A4 | E16: ADD | G16: 50 | H16: Rim | I16: 65000 | J16: =I16*G16 -> 3250000
C17: 02 | D17: Kertas HVS F4 | E17: ADD | G17: 100 | H17: Rim | I17: 75000 | J17: =I17*G17 -> 7500000
C18: 03 | D18: Tinta Printer | E18: ADD | G18: 10 | H18: Pkt | I18: 500000 | J18: =I18*G18 -> 5000000
C19: 04 | D19: Map L | E19: ADD | G19: 25 | H19: Pak | I19: 25000 | J19: =I19*G19 -> 625000
C20: 05 | D20: Map Kancing | E20: ADD | G20: 15 | H20: Pak | I20: 35000 | J20: =I20*G20 -> 525000
C21: 06 | D21: Map Kertas | E21: ADD | G21: 250 | H21: Bh | I21: 10000 | J21: =I21*G21 -> 2500000
C22: 07 | D22: Bulpoint | E22: ADD | G22: 30 | H22: Pak | I22: 35000 | J22: =I22*G22 -> 1050000
C23: 08 | D23: Spidol | E23: ADD | G23: 1 | H23: Pak | I23: 95000 | J23: =I23*G23 -> 95000
C24: 09 | D24: Tinta Stampel | E24: ADD | G24: 5 | H24: Bh | I24: 35000 | J24: =I24*G24 -> 175000
C25: 10 | D25: Bak Stampel | E25: ADD | G25: 5 | H25: Bh | I25: 15000 | J25: =I25*G25 -> 75000
C26: 11 | D26: Stapler | E26: ADD | G26: 20 | H26: Bh | I26: 25000 | J26: =I26*G26 -> 500000
C27: 12 | D27: Isi Stapler | E27: ADD | G27: 10 | H27: Box | I27: 35000 | J27: =I27*G27 -> 350000
... C50: 35 | D50: Meja Dada | E50: ADD | G50: 10 | H50: Bh | I50: 20000 | J50: =I50*G50 -> 200000
B51: Belanja Pakaian Dinas | J51: =J52 -> 10500000
A52: 5.1.1.01. | C52: Belanja Pakaian Dinas/Seragam/Atribut | J52: =SUM(J53:J56) -> 10500000
C53: 01 | D53: Topi Dinas | E53: ADD | G53: 15 | H53: Bh | I53: 100000 | J53: =I53*G53 -> 1500000 | L53: =J82-J74 -> 136090000
C54: 02 | D54: Atribut Lainnya | E54: ADD | G54: 15 | H54: Bh | I54: 100000 | J54: =I54*G54 -> 1500000
C55: 03 | D55: Jaket Dinas | E55: ADD | G55: 15 | H55: Bh | I55: 300000 | J55: =I55*G55 -> 4500000
C56: 04 | D56: Seragam PDH | E56: ADD | G56: 15 | H56: Bh | I56: 200000 | J56: =I56*G56 -> 3000000
A57: 5.2.1. | B57: Belanja Konsumsi | J57: =J58 -> 15000000
A58: 5.2.1.06. | C58: Belanja Makan dan Minum | J58: =SUM(J59:J59) -> 15000000
C59: 01 | D59: Konsumsi (Kotak/Prasmanan/Minum) | E59: ADD | G59: 600 | H59: Porsi | I59: 25000 | J59: =I59*G59 -> 15000000
A60: 5.2.2. | B60: Belanja Jasa Honorarium | J60: =J61 -> 34200000 | L60: Dasar Hukum: Peraturan Bupati Malang Nomor 130 tentang Standar Biaya Umum Desa Tahun 2024, dalam Lampiran angka 1, Huruf A
A61: 5.2.2.06 | C61: Belanja Jasa Honorarium PKPKD dan PPKD | J61: =SUM(J62:J65) -> 34200000
C62: 01 | D62: PKPKD | E62: ADD | G62: 12 | H62: OB | I62: 600000 | J62: =I62*G62 -> 7200000
C63: 02 | D63: Koordinator PPKD | E63: ADD | G63: 12 | H63: OB | I63: 400000 | J63: =I63*G63 -> 4800000
...

Sheet BPD
A1: RENCANA ANGGARAN BIAYA (RAB)
A2: PEMERINTAH DESA PANDANLANDUNG | L2: Check Sum:
A3: TAHUN ANGGARAN 2026 | L3: ADD | M3: =J15 -> 58800000
L4: DDS | M4: 0
A5: Bidang | C5: : | D5: PENYELENGGARAAN PEMERINTAHAN DESA
A6: Kegiatan | C6: : | D6: Penyediaan Tunjangan BPD
A7: Waktu | C7: : | D7: 12 Bulan
A8: Output | C8: : | D8: Pembayaran Tunjangan BPD
A10: KODE | B10: U R A I A N | G10: RINCIAN
G11: VOLUME | I11: HARGA SATUAN | J11: JUMLAH (Rp)
A12: 1 | B12: 2 | G12: 3 | I12: 4 | J12: 5
A13: 5 | B13: BELANJA | J13: =J14 -> 58800000
A14: 5.1.4. | B14: Tunjangan Kedudukan BPD | J14: =J15 -> 58800000 | L14: Dasar Hukum: Peraturan Bupati Malang Nomor 202 Tahun 2022 tentang Pendapatan Kades, Perangkat Desa, Tunjangan BPD, dan Insentif Ketua RT dan Ketua RW (Pasal 11)
A15: 5.1.4.01 | C15: Tunjangan Kedudukan BPD | J15: =SUM(J16:J19) -> 58800000
C16: 01 | D16: Ketua | E16: ADD | G16: 12 | H16: OB | I16: 750000 | J16: =I16*G16 -> 9000000
C17: 02 | D17: Wakil Ketua | E17: ADD | G17: 12 | H17: OB | I17: 600000 | J17: =I17*G17 -> 7200000
C18: 03 | D18: Sekretaris | E18: ADD | G18: 12 | H18: OB | I18: 550000 | J18: =I18*G18 -> 6600000
C19: 04 | D19: Anggota | E19: ADD | G19: 72 | H19: OB | I19: 500000 | J19: =I19*G19 -> 36000000
B20: JUMLAH (Rp) | J20: =J13 -> 58800000
G22: Pandanlandung, 29 November 2025
A23: Pj. Kepala Desa Pandanlandung | G23: Pelaksana Kegiatan
A27: HARI SULISTIONO, S.AP | G27: NOVIA RAHAYU

Sheet OPS BPD
A1: RENCANA ANGGARAN BIAYA (RAB)
A2: PEMERINTAH DESA PANDANLANDUNG | L2: Check Sum:
A3: TAHUN ANGGARAN 2026 | L3: ADD | M3: =J17 -> 4000000
L4: DDS | M4: 0
A5: Bidang | C5: : | D5: PENYELENGGARAAN PEMERINTAHAN DESA
A6: Kegiatan | C6: : | D6: Penyediaan Operasional BPD (Rapat, ATK, Konsumsi, Pakaian Seragam, dll) | K6: rinci
A7: Waktu | C7: : | D7: 12 Bulan
A8: Output | C8: : | D8: Bantuan Operasional BPD
A10: KODE | B10: U R A I A N | G10: RINCIAN
G11: VOLUME | I11: HARGA SATUAN | J11: JUMLAH (Rp)
A12: 1 | B12: 2 | G12: 3 | I12: 4 | J12: 5
A13: 5 | B13: BELANJA | J13: =J14 -> 4000000 | L13: Dasar Hukum: Peraturan Bupati Malang Nomor 202 Tahun 2022 tentang Pendapatan Kades, Perangkat Desa, Tunjangan BPD, dan Insentif Ketua RT dan Ketua RW (Pasal 11, ayat (8))
A14: 1.01.06 | B14: Bantuan Operasional BPD | J14: =J15 -> 4000000
A15: 5.2.5 | C15: Belanja Operasional Perkantoran | J15: =SUM(J16:J16) -> 4000000
C16: 01 | D16: Operasional BPD | E16: ADD | G16: 1 | H16: LS | I16: 4000000 | J16: =I16*G16 -> 4000000
B17: JUMLAH (Rp) | J17: =J13 -> 4000000
G19: Pandanlandung, 29 November 2025
A20: Pj. Kepala Desa Pandanlandung | G20: Pelaksana Kegiatan
A24: HARI SULISTIONO, S.AP | G24: NOVIA RAHAYU

Sheet RT RW
A1: RENCANA ANGGARAN BIAYA (RAB)
A2: PEMERINTAH DESA PANDANLANDUNG | L2: Check Sum:
A3: TAHUN ANGGARAN 2026 | L3: ADD | M3: =J18 -> 143940000
L4: DDS | M4: 0
A5: Bidang | C5: : | D5: PENYELENGGARAAN PEMERINTAHAN DESA
A6: Kegiatan | C6: : | D6: Penyediaan Insentif / Operasional RT/RW
A7: Waktu | C7: : | D7: 12 Bulan
A8: Output | C8: : | D8: Insentif RT dan RW
A10: KODE | B10: U R A I A N | G10: RINCIAN
G11: VOLUME | I11: HARGA SATUAN | J11: JUMLAH (Rp)
A12: 1 | B12: 2 | G12: 3 | I12: 4 | J12: 5
A13: 5 | B13: BELANJA | J13: =J14 -> 143940000 | L13: Dasar Hukum: Peraturan Bupati Malang Nomor 202 Tahun 2022 tentang Pendapatan Kades, Perangkat Desa, Tunjangan BPD, dan Insentif Ketua RT dan Ketua RW (Pasal 12)
A14: 5.2.5. | B14: Belanja Operasional RT RW | J14: =J15 -> 143940000
A15: 5.2.5.08. | C15: Belanja Operasional RT/RW | J15: =SUM(J16:J17) -> 143940000
C16: 01 | D16: Insentif Ketua RW (7 Org x 12 Bulan) | E16: ADD | G16: 84 | H16: OB | I16: 275000 | J16: =I16*G16 -> 23100000
C17: 02 | D17: Insentif Ketua RT (38 Org x 12 Bulan) | E17: ADD | G17: 456 | H17: OB | I17: 265000 | J17: =I17*G17 -> 120840000
B18: JUMLAH (Rp) | J18: =J13 -> 143940000
G20: Pandanlandung, 29 November 2025
A21: Pj. Kepala Desa Pandanlandung | G21: Pelaksana Kegiatan
A25: HARI SULISTIONO, S.AP | G25: CAHYA DWI ANANTA

Sheet OPS PEMDES 3%
A1: RENCANA ANGGARAN BIAYA (RAB)
A2: PEMERINTAH DESA PANDANLANDUNG | L2: Check Sum:
A3: TAHUN ANGGARAN 2026 | L3: ADD | M3: 0
L4: DDS | M4: =SUM(J16:J27) -> 38129000
A5: Bidang | C5: : | D5: PENYELENGGARAAN PEMERINTAHAN DESA
A6: Kegiatan | C6: : | D6: Penyediaan Operasional Pemerintah Desa yang bersumber dari Dana Desa
A7: Waktu | C7: : | D7: 12 Bulan
A8: Output | C8: : | D8: Operasional Pemdes 3% dari Dana Desa
A10: KODE | B10: U R A I A N | G10: RINCIAN
G11: VOLUME | I11: HARGA SATUAN | J11: JUMLAH (Rp)
A12: 1 | B12: 2 | G12: 3 | I12: 4 | J12: 5
A13: 5 | B13: BELANJA | J13: =J14 -> 38129000
A14: 1.01.08 | B14: Dukungan Kegiatan Seremonial Desa | J14: =J15 -> 38129000
A15: 5.2.1.99. | C15: Belanja Barang dan Perlengkapan lainnya | J15: =SUM(J16:J27) -> 38129000
C16: 01 | D16: Sewa Terop Riging | E16: DDS | G16: 1 | H16: Unit | I16: 2000000 | J16: =I16*G16 -> 2000000 | O16: =SUM(O17:O36,O39) -> 4129000
C17: 02 | D17: Sewa Sound System | E17: DDS | G17: 1 | H17: Pkt | I17: 6000000 | J17: =I17*G17 -> 6000000 | L17: Piring Makan | M17: 200 | N17: 3000 | O17: =N17*M17 -> 600000
C18: 03 | D18: Dekorasi | E18: DDS | G18: 1 | H18: Pkt | I18: 3000000 | J18: =I18*G18 -> 3000000 | L18: Sendok | M18: 200 | N18: 2000 | O18: =N18*M18 -> 400000
C19: 04 | D19: Publikasi | E19: DDS | G19: 1 | H19: Pkt | I19: 2000000 | J19: =I19*G19 -> 2000000 | L19: Piring Rampatan | M19: 20 | N19: 10000 | O19: =N19*M19 -> 200000
C20: 05 | D20: Panggung 4x10 | E20: DDS | G20: 1 | H20: Unit | I20: 2500000 | J20: =I20*G20 -> 2500000 | L20: Mangkok Es | M20: 200 | N20: 2000 | O20: =N20*M20 -> 400000
C21: 06 | D21: Sewa Kursi VIP | E21: DDS | G21: 1000 | H21: Bh | I21: 7000 | J21: =I21*G21 -> 7000000 | L21: Sendok Es | M21: 200 | N21: 1000 | O21: =N21*M21 -> 200000
C22: 07 | D22: Lighting | E22: DDS | G22: 1 | H22: Pkt | I22: 5000000 | J22: =I22*G22 -> 5000000 | L22: Mangkok Es Besar | M22: 2 | N22: 35000 | O22: =N22*M22 -> 70000
C23: 08 | D23: Konsumsi Pembentukan Panitia | E23: DDS | G23: 80 | H23: Org | I23: 25000 | J23: =I23*G23 -> 2000000 | L23: Food Warmer Kotak | M23: 4 | N23: 45000 | O23: =N23*M23 -> 180000
C24: 09 | D24: Sewa Kursi VVIP | E24: DDS | G24: 10 | H24: Bh | I24: 250000 | J24: =I24*G24 -> 2500000 | L24: Food Warmer Bulat | M24: 4 | N24: 45000 | O24: =N24*M24 -> 180000
C25: 10 | D25: Konsumsi Rakor Panitia 2x | E25: DDS | G25: 80 | H25: Org | I25: 25000 | J25: =I25*G25 -> 2000000 | L25: Kompor Joss | M25: 5 | N25: 75000 | O25: =N25*M25 -> 375000
C26: 11 | D26: ATK | E26: DDS | G26: 1 | H26: Pkt | I26: 129000 | J26: =I26*G26 -> 129000 | L26: Kompor Gas | M26: 10 | N26: 45000 | O26: =N26*M26 -> 450000
C27: 12 | D27: Sewa Peralatan Makan | E27: DDS | G27: 1 | H27: Pkt | I27: 4000000 | J27: =I27*G27 -> 4000000 | L27: Dandang 5Kg | M27: 2 | N27: 35000 | O27: =N27*M27 -> 70000
B28: JUMLAH (Rp) | J28: =J13 -> 38129000 | L28: Meja Prasmanan Panjang | M28: 3 | N28: 75000 | O28: =N28*M28 -> 225000
L29: Meja Es Bulat | M29: 1 | N29: 55000 | O29: =N29*M29 -> 55000
G30: Pandanlandung, 29 November 2025 | L30: Tremos Kopi | M30: 4 | N30: 35000 | O30: =N30*M30 -> 140000
A31: Pj. Kepala Desa Pandanlandung | G31: Pelaksana Kegiatan | L31: Tremos Nasi | M31: 4 | N31: 35000 | O31: =N31*M31 -> 140000
L32: Panci Besar | M32: 2 | N32: 35000 | O32: =N32*M32 -> 70000
L33: Panci Sedang | M33: 1 | N33: 30000 | O33: =N33*M33 -> 30000
L34: Centong Nasi | M34: 5 | N34: 15000 | O34: =N34*M34 -> 75000
A35: HARI SULISTIONO, S.AP | G35: CAHYA DWI ANANTA
L36: Termos Es | M36: 4 | N36: 35000 | O36: =N36*M36 -> 140000
O37: =N37*M37 -> 0
O38: =N38*M38 -> 0
K39: AtK | O39: =SUM(O40:O46) -> 129000
L40: Id Card | M40: 43 | N40: 3000 | O40: =N40*M40 -> 129000
O42: =N42*M42 -> 0

Sheet SARPRAS KANTOR DESA
A1: RENCANA ANGGARAN BIAYA (RAB)
A2: PEMERINTAH DESA PANDANLANDUNG | L2: Check Sum:
A3: TAHUN ANGGARAN 2026 | L3: PBH | M3: =J15+J17+J22+J25+J37 -> 147145000
L4: DDS | M4: 0
A5: Bidang | C5: : | D5: PENYELENGGARAAN PEMERINTAHAN DESA | L5: ADD | M5: =J30+J34+J39 -> 28050000
A6: Kegiatan | C6: : | D6: Penyediaan Sarana (Aset Tetap) Perkantoran/Pemerintahan
A7: Waktu | C7: : | D7: 12 Bulan
A8: Output | C8: : | D8: Sarana dan Prasarana Kantor Desa
A10: KODE | B10: U R A I A N | G10: RINCIAN
G11: VOLUME | I11: HARGA SATUAN | J11: JUMLAH (Rp)
A12: 1 | B12: 2 | G12: 3 | I12: 4 | J12: 5
A13: 5 | B13: BELANJA | J13: =J14+J29+J34+J36+J39 -> 175195000
A14: 1.02.03. | B14: Belanja Modal Lainnya | J14: =J15+J17+J22+J25 -> 124645000
A15: 5.2.1.02 | C15: Belanja Peralatan Listrik | J15: =SUM(J16:J16) -> 3400000
C16: 01 | D16: HDMI Wireless | E16: PBH | G16: 2 | H16: Bh | I16: 1700000 | J16: =I16*G16 -> 3400000
A17: 5.2.1.03 | C17: Belanja Perlengkapan Alat rumah Tangga | J17: =SUM(J18:J21) -> 1530000
C18: 01 | D18: Selang Air | E18: PBH | G18: 50 | H18: M | I18: 25000 | J18: =I18*G18 -> 1250000
C19: 02 | D19: Sapu Atap | E19: PBH | G19: 2 | H19: Bh | I19: 40000 | J19: =I19*G19 -> 80000
C20: 03 | D20: Pengki | E20: PBH | G20: 2 | H20: Bh | I20: 30000 | J20: =I20*G20 -> 60000
C21: 04 | D21: Pel Lantai | E21: PBH | G21: 2 | H21: Bh | I21: 70000 | J21: =I21*G21 -> 140000
A22: 5.2.1.04 | C22: Belanja Modal Peralatan Elektronik dan Alat Studio | J22: =SUM(J23:J24) -> 116765000
C23: 01 | D23: Video Trond | E23: PBH | G23: 1 | H23: Unit | I23: 110250000 | J23: =I23*G23 -> 110250000
C24: 02 | D24: Sound System Gantung | E24: PBH | G24: 1 | H24: Pkt | I24: 6515000 | J24: =I24*G24 -> 6515000
A25: 5.2.1.05 | C25: Belanja Modal Peralatan Dapur | J25: =SUM(J26:J28) -> 2950000
C26: 01 | D26: Gelas | E26: PBH | G26: 5 | H26: Set | I26: 150000 | J26: =I26*G26 -> 750000
C27: 02 | D27: Piring | E27: PBH | G27: 100 | H27: Bh | I27: 17000 | J27: =I27*G27 -> 1700000
C28: 03 | D28: Sendok | E28: PBH | G28: 100 | H28: Bh | I28: 5000 | J28: =I28*G28 -> 500000
B29: Belanja Modal Laptop Kantor | J29: =SUM(J30) -> 26500000
A30: 5.3.2.03 | C30: Belanja Modal Peralatan Komputer | J30: =SUM(J31:J32) -> 26500000
C31: 01 | D31: Komputer | E31: ADD | G31: 2 | H31: Unit | I31: 8000000 | J31: =I31*G31 -> 16000000
C32: 02 | D32: Printer | E32: ADD | G32: 3 | H32: Unit | I32: 3500000 | J32: =I32*G32 -> 10500000
B33: Belanja Mebelair Kantor
A34: 5.3.2.04 | C34: Belanja Modal Peralatan Mebelai dan aksesoris | J34: =SUM(J35:J35) -> 600000
C35: 01 | D35: Rak Kertas | E35: ADD | G35: 2 | H35: Unit | I35: 300000 | J35: =I35*G35 -> 600000
B36: Belanja Mebelair Kantor | J36: =SUM(J37) -> 22500000
A37: 5.3.2.05 | C37: Belanja Modal Peralatan Mebelair dan aksesoris | J37: =SUM(J38) -> 22500000
C38: 01 | D38: Kitchen Set | E38: PBH | G38: 1 | H38: Unit | I38: 22500000 | J38: =I38*G38 -> 22500000
B39: Belanja Modal Lainnya | J39: =J40 -> 950000
A40: 5.2.1.02 | C40: Belanja Peralatan Listrik | J40: =SUM(J41:J42) -> 950000
C41: 01 | D41: Lampu Kantor | E41: ADD | G41: 10 | H41: Bh | I41: 70000 | J41: =I41*G41 -> 700000
...

Sheet SUN RKP
A1: RENCANA ANGGARAN BIAYA (RAB)
A2: PEMERINTAH DESA PANDANLANDUNG | L2: Check Sum:
A3: TAHUN ANGGARAN 2026 | L3: PBH | M3: 0
L4: DDS | M4: =J13 -> 2705000
A5: Bidang | C5: : | D5: PENYELENGGARAAN PEMERINTAHAN DESA
A6: Kegiatan | C6: : | D6: Penyusunan Dokumen Perencanaan Desa dan Keuangan Desa (RPJMDes, RKPDes)
A7: Waktu | C7: : | D7: 12 Bulan
A8: Output | C8: : | D8: Penyusunan RKPDes dan APBDesa
A10: KODE | B10: U R A I A N | G10: RINCIAN
G11: VOLUME | I11: HARGA SATUAN | J11: JUMLAH (Rp)
A12: 1 | B12: 2 | G12: 3 | I12: 4 | J12: 5
A13: 5 | B13: BELANJA | J13: =J14 -> 2705000
A14: 1.04.02. | B14: Penyelenggaraan Musdes RKPDesa | J14: =J15+J25+J22 -> 2705000
A15: 5.2.1. | B15: Belanja Barang dan Perlengkapan | J15: =J16 -> 975000 | L15: Dasar Hukum: Permendesa PDTT Nomor 7 Tahun 2023 tentang Prioritas Penggunaan Dana Desa, dalam Pasal 6 huruf b
A16: 5.1.1.01. | C16: Belanja Alat Tulis Kantor dan Benda Pos | J16: =SUM(J17:J21) -> 975000
C17: 01 | D17: Bulpoint | E17: DDS | G17: 1 | H17: Pak | I17: 30000 | J17: =I17*G17 -> 30000
C18: 02 | D18: Kertas HVS F4 | E18: DDS | G18: 1 | H18: RIM | I18: 65000 | J18: =I18*G18 -> 65000
C19: 03 | D19: Pilox | E19: DDS | G19: 4 | H19: Bh | I19: 35000 | J19: =I19*G19 -> 140000
C20: 04 | D20: Meteran | E20: DDS | G20: 1 | H20: Bh | I20: 500000 | J20: =I20*G20 -> 500000
C21: 05 | D21: Cetak Banner 2x3 m | E21: DDS | G21: 2 | H21: Bh | I21: 120000 | J21: =I21*G21 -> 240000
B22: Belanja Sewa Peralatan Lainnya | J22: =J23 -> 280000
C23: Belanja Sewa Perlengkapan | J23: =SUM(J24:J24) -> 280000
C24: 01 | D24: Sewa Kursi Susun | E24: DDS | G24: 40 | H24: Unit | I24: 7000 | J24: =I24*G24 -> 280000
A25: 5.2.2. | B25: Belanja Jasa Honorarium | J25: =J26 -> 1450000
A26: 5.2.3.96. | C26: Belanja Jasa Honorarium Panitia Pelaksana Kegiatan | J26: =SUM(J27:J32) -> 1450000 | L26: Dasar Hukum: Peraturan Bupati Malang Nomor 184 Tahun 2024 tentang Standar Biaya Umum Desa Tahun 2025, lampiran angka 1 huruf m, n
C27: 01 | D27: Ketua Tim Verifikasi | E27: DDS | G27: 1 | H27: OB | I27: 200000 | J27: =I27*G27 -> 200000
C28: 02 | D28: Sekretaris Tim Verifikasi | E28: DDS | G28: 1 | H28: OB | I28: 150000 | J28: =I28*G28 -> 150000
C29: 03 | D29: Anggota Tim Verifikasi | E29: DDS | G29: 3 | H29: OB | I29: 100000 | J29: =I29*G29 -> 300000
C30: 04 | D30: Ketua Tim Penyusun | E30: DDS | G30: 1 | H30: OB | I30: 200000 | J30: =I30*G30 -> 200000
C31: 05 | D31: Sekretaris Tim Penyusun | E31: DDS | G31: 1 | H31: OB | I31: 100000 | J31: =I31*G31 -> 100000
C32: 06 | D32: Anggota Tim Penyusun | E32: DDS | G32: 5 | H32: OB | I32: 100000 | J32: =I32*G32 -> 500000
B33: JUMLAH (Rp) | J33: =J13 -> 2705000
G35: Pandanlandung, 29 November 2025
A36: Pj. Kepala Desa Pandanlandung | G36: Pelaksana Kegiatan
A40: HARI SULISTIONO, S.AP | G40: CAHYA DWI ANANTA

Sheet Sun APBDes
A1: RENCANA ANGGARAN BIAYA (RAB)
A2: PEMERINTAH DESA PANDANLANDUNG | L2: Check Sum:
A3: TAHUN ANGGARAN 2026 | L3: PBH | M3: 0
L4: DDS | M4: =J13 -> 4430000
A5: Bidang | C5: : | D5: PENYELENGGARAAN PEMERINTAHAN DESA
A6: Kegiatan | C6: : | D6: Penyelenggaan Musyawarah Perencanaan Desa APBDes (Reguler)
A7: Waktu | C7: : | D7: 12 Bulan
A8: Output | C8: : | D8: Musyawarah Desa Reguler
A10: KODE | B10: U R A I A N | G10: RINCIAN
G11: VOLUME | I11: HARGA SATUAN | J11: JUMLAH (Rp)
A12: 1 | B12: 2 | G12: 3 | I12: 4 | J12: 5
A13: 5 | B13: BELANJA | J13: =J14 -> 4430000
A14: 1.04.08. | B14: Penyelenggaraan Musdes APBDesa | J14: =J19+J15 -> 4430000
B15: Belanja Barang dan Perlengkapan | J15: =J16 -> 180000 | L15: Dasar Hukum: Permendesa PDTT Nomor 7 Tahun 2023 tentang Prioritas Penggunaan Dana Desa, dalam Pasal 6 huruf b
C16: Belanja Alat Tulis Kantor dan Benda Pos | J16: =SUM(J17:J18) -> 180000
C17: 01 | D17: Cetak Banner 2x3 m | E17: DDS | G17: 1 | H17: Bh | I17: 120000 | J17: =I17*G17 -> 120000
C18: 02 | D18: Bulpoint | E18: DDS | G18: 2 | H18: Pak | I18: 30000 | J18: =I18*G18 -> 60000
A19: 5.2.1. | B19: Belanja Konsumsi | J19: =J20 -> 4250000
A20: 5.2.1.06. | C20: Belanja Makan dan Minum | J20: =SUM(J21:J22) -> 4250000
C21: 01 | D21: Konsumsi Musdes APBDesa | E21: DDS | G21: 85 | H21: Porsi | I21: 25000 | J21: =I21*G21 -> 2125000
C22: 02 | D22: Konsumsi Musdes Penetapan APBDesa | E22: DDS | G22: 85 | H22: Porsi | I22: 25000 | J22: =I22*G22 -> 2125000
B23: JUMLAH (Rp) | J23: =J13 -> 4430000
G25: Pandanlandung, 29 November 2025
A26: Pj. Kepala Desa Pandanlandung | G26: Pelaksana Kegiatan
A30: HARI SULISTIONO, S.AP | G30: CAHYA DWI ANANTA

Sheet NONREGULER
A1: RENCANA ANGGARAN BIAYA (RAB)
A2: PEMERINTAH DESA PANDANLANDUNG | L2: Check Sum:
A3: TAHUN ANGGARAN 2026 | L3: PAD | M3: =J13 -> 2000000
L4: DDS | M4: =0 -> 0
A5: Bidang | C5: : | D5: PENYELENGGARAAN PEMERINTAHAN DESA
A6: Kegiatan | C6: : | D6: Penyelenggaraan Musyawarah Desa Lainnya (Musdus, Rembug Desa Non Reguler)
A7: Waktu | C7: : | D7: 12 Bulan
A8: Output | C8: : | D8: Penyelenggaraan Musyawarah Desa Non Reguler
A10: KODE | B10: U R A I A N | G10: RINCIAN
G11: VOLUME | I11: HARGA SATUAN | J11: JUMLAH (Rp)
A12: 1 | B12: 2 | G12: 3 | I12: 4 | J12: 5
A13: 5 | B13: BELANJA | J13: =J15+J21 -> 2000000
A14: 1.04.02. | B14: Penyelenggaraan Musdes Penggalian Aspirasi
A15: 5.2.1. | B15: Belanja Barang dan Perlengkapan | J15: =J16 -> 500000
A16: 5.1.1.01. | C16: Belanja Alat Tulis Kantor dan Benda Pos | J16: =SUM(J17:J20) -> 500000 | L16: Memfasilitasi rembug di Desa seperti: Musyawarah Panitia Bersih Desa, HUT RI, Rapat LKD, Penggalian aspirasi sebagai bahan penyusunan regulasi desa.
C17: 01 | D17: Map L | E17: PAD | G17: 2 | H17: Pak | I17: 25000 | J17: =I17*G17 -> 50000
C18: 02 | D18: Bulpoint | E18: PAD | G18: 7 | H18: Pak | I18: 35000 | J18: =I18*G18 -> 245000
C19: 03 | D19: Kertas HVS F4 | E19: PAD | G19: 2 | H19: Rim | I19: 65000 | J19: =I19*G19 -> 130000
C20: 04 | D20: Tape X | E20: PAD | G20: 10 | H20: Bh | I20: 7500 | J20: =I20*G20 -> 75000
A21: 5.2.1. | B21: Belanja Konsumsi | J21: =J22 -> 1500000
A22: 5.2.1.06. | C22: Belanja Makan dan Minum | J22: =SUM(J23:J23) -> 1500000
C23: 01 | D23: Konsumsi | E23: PAD | G23: 60 | H23: porsi | I23: 25000 | J23: =I23*G23 -> 1500000
B24: JUMLAH (Rp) | J24: =J13 -> 2000000
G26: Pandanlandung, 29 November 2025
A27: Pj. Kepala Desa Pandanlandung | G27: Pelaksana Kegiatan
A31: HARI SULISTIONO, S.AP | G31: CAHYA DWI ANANTA

Sheet SUN KEBIJAKAN DESA
A1: RENCANA ANGGARAN BIAYA (RAB)
A2: PEMERINTAH DESA PANDANLANDUNG
A3: TAHUN ANGGARAN 2026
A5: Bidang | C5: : | D5: PENYELENGGARAAN PEMERINTAHAN DESA | L5: Check Sum:
A6: Kegiatan | C6: : | D6: Penyusunan Kebijakan Desa (Peraturan Desa, Peraturan Kepala Desa, selain RKPDes dan APBDes) | L6: DLL | M6: 0
A7: Waktu | C7: : | D7: 12 Bulan | L7: PBH | M7: =J13 -> 500000
A8: Output | C8: : | D8: Penyusunan Peraturan di Desa (Non Reguler)
A10: KODE | B10: U R A I A N | G10: RINCIAN
G11: VOLUME | I11: HARGA SATUAN | J11: JUMLAH (Rp)
A12: 1 | B12: 2 | G12: 3 | I12: 4 | J12: 5
A13: 5 | B13: BELANJA | J13: =J15 -> 500000
A14: 1.04.06. | B14: Bantuan Operasional Penyusunan Draf Kebijakan Desa
A15: 5.2.1. | B15: Belanja Barang dan Perlengkapan | J15: =J16 -> 500000
A16: 5.1.1.01. | C16: Belanja Alat Tulis Kantor dan Benda Pos | J16: =SUM(J17:J20,L16) -> 500000 | L16: Penyusunan dan Penetapan Peraturan Desa seperti: Perdes Lingkungan Hidup, BUMDesa, dll
C17: 01 | D17: Map L | E17: PBH | G17: 2 | H17: Pak | I17: 25000 | J17: =I17*G17 -> 50000
C18: 02 | D18: Bulpoint | E18: PBH | G18: 7 | H18: Pak | I18: 35000 | J18: =I18*G18 -> 245000
C19: 03 | D19: Kertas HVS F4 | E19: PBH | G19: 2 | H19: Rim | I19: 65000 | J19: =I19*G19 -> 130000
C20: 04 | D20: Tipe x | E20: PBH | G20: 10 | H20: Bh | I20: 7500 | J20: =I20*G20 -> 75000
B21: JUMLAH (Rp) | J21: =J13 -> 500000
G23: Pandanlandung, 29 November 2025
A24: Pj. Kepala Desa Pandanlandung | G24: Pelaksana Kegiatan
A28: HARI SULISTIONO, S.AP | G28: CAHYA DWI ANANTA

Sheet SPPT PBB
A1: RENCANA ANGGARAN BIAYA (RAB)
A2: PEMERINTAH DESA PANDANLANDUNG | L2: Check Sum:
A3: TAHUN ANGGARAN 2026 | L3: DLL | M3: 0
L4: PBH | M4: =J16+J17 -> 20330000
A5: Bidang | C5: : | D5: PENYELENGGARAAN PEMERINTAHAN DESA
A6: Kegiatan | C6: : | D6: Administrasi Pajak Bumi dan Bangunan (PBB)
A7: Waktu | C7: : | D7: 12 Bulan
A8: Output | C8: : | D8: Insentif Petugas Penyampaian dan Penagihan SPPT PBB
A10: KODE | B10: U R A I A N | G10: RINCIAN
G11: VOLUME | I11: HARGA SATUAN | J11: JUMLAH (Rp)
A12: 1 | B12: 2 | G12: 3 | I12: 4 | J12: 5
A13: 5 | B13: BELANJA | J13: =J14 -> 20330000
A14: 5.2.2. | B14: Belanja Jasa Honorarium | J14: =J15 -> 20330000 | L14: Dasar Hukum: Peraturan Bupati Malang Nomor 130 tentang Standar Biaya Umum Desa Tahun 2024, dalam Lampiran angka 6
A15: 5.2.2.99. | C15: Belanja Jasa Honorarium Lainnya | J15: =SUM(J16:J17) -> 20330000
C16: 01 | D16: Jasa Penyampaian SPPT PBB | E16: PBH | G16: 4066 | H16: Lbr | I16: 2000 | J16: =I16*G16 -> 8132000
C17: 02 | D17: Jasa Penagihan SPPT PBB | E17: PBH | G17: 4066 | H17: Lbr | I17: 3000 | J17: =I17*G17 -> 12198000
B18: JUMLAH (Rp) | J18: =J13 -> 20330000 | L18: Besaran upah penyampaian, 2.000 per lembar, dan Penagihan 3.000 per lembar
G20: Pandanlandung, 29 November 2025
A21: Pj. Kepala Desa Pandanlandung | G21: Pelaksana Kegiatan
A25: HARI SULISTIONO, S.AP | G25: CAHYA DWI ANANTA

Sheet OPERASIONAL PAJAK
A1: RENCANA ANGGARAN BIAYA (RAB)
A2: PEMERINTAH DESA PANDANLANDUNG | L2: Check Sum:
A3: TAHUN ANGGARAN 2026 | L3: DLL | M3: =J13 -> 2514000
L4: PBH
A5: Bidang | C5: : | D5: PENYELENGGARAAN PEMERINTAHAN DESA
A6: Kegiatan | C6: : | D6: Penyediaan Operasional Pemerintah Desa (Pajak)
A7: Waktu | C7: : | D7: 12 Bulan
A8: Output | C8: : | D8: Belanja Operasional Perkantoran
A10: KODE | B10: U R A I A N | G10: RINCIAN
G11: VOLUME | I11: HARGA SATUAN | J11: JUMLAH (Rp)
A12: 1 | B12: 2 | G12: 3 | I12: 4 | J12: 5
A13: 5 | B13: BELANJA | J13: =J14 -> 2514000
A14: 5.2.2. | B14: Belanja Operasional Perkantoran | J14: =J15+J18 -> 2514000 | L14: Dasar Hukum: Peraturan Bupati Malang Nomor 130 tentang Standar Biaya Umum Desa Tahun 2024, dalam Lampiran angka 6
A15: 5.2.2.99. | C15: Belanja Jasa Perpanjangan Ijin/Pajak | J15: =SUM(J16) -> 2214000
C16: 01 | D16: Pajak Atas Bunga Bank | E16: DLL | G16: 1 | H16: Tahun | I16: 2214000 | J16: =I16*G16 -> 2214000
C17: Belanja Operasional Perkantoran lainnya
C18: 01 | D18: Biaya Admin Bank | E18: DLL | G18: 1 | H18: Tahun | I18: 300000 | J18: =I18*G18 -> 300000
B19: JUMLAH (Rp) | J19: =J13 -> 2514000 | L19: Besaran upah penyampaian, 2.000 per lembar, dan Penagihan 3.000 per lembar
G21: Pandanlandung, 29 November 2025
A22: Pj. Kepala Desa Pandanlandung | G22: Pelaksana Kegiatan
A26: HARI SULISTIONO, S.AP | G26: CAHYA DWI ANANTA

Sheet PAUD TPQ
A1: RENCANA ANGGARAN BIAYA (RAB)
A2: PEMERINTAH DESA PANDANLANDUNG | L2: Check Sum:
A3: TAHUN ANGGARAN 2026 | L3: DDS | M3: =J17 -> 24000000
L4: PBH | M4: 0
A5: Bidang | C5: : | D5: PELAKSANAAN PEMBANGUNAN DESA
A6: Kegiatan | C6: : | D6: Penyelanggaraan PAUD.TPA/TKA/TPQ/Madrasah Non Formal Milik Desa (Honor, Pakaian, dll)
A7: Waktu | C7: : | D7: 12 Bulan
A8: Output | C8: : | D8: Honor/Insentif Guru TPQ dan PAUD
A10: KODE | B10: U R A I A N | G10: RINCIAN
G11: VOLUME | I11: HARGA SATUAN | J11: JUMLAH (Rp)
A12: 1 | B12: 2 | G12: 3 | I12: 4 | J12: 5
A13: 5 | B13: BELANJA | J13: =J15 -> 24000000
A14: 2.01.01 | B14: Bantuan Honor/Insentif Guru TPQ dan PAUD | L14: Dasar Hukum: Permendesa PDTT Nomor 13 Tahun 2023 tentang Petunjuk Operasional Penggunaan Dana Desa 2024, dalam Lampirannya, disebutkan dalam BAB II Huruf C angka 4, poin f dan Permendesa PDTT Nomor 7 Tahun 2023 BAB II Huruf A angka 2, poin f.
A15: 5.2.2. | B15: Belanja Jasa Honorarium | J15: =J16 -> 24000000
A16: 5.2.2.99. | C16: Belanja Jasa Honorarium Lainnya | J16: =SUM(J17:J17) -> 24000000
C17: 01 | D17: Insentif Guru Pengajar Ngaji/TPQ | E17: DDS | G17: 480 | H17: OB | I17: 50000 | J17: =I17*G17 -> 24000000
B18: JUMLAH (Rp) | J18: =J13 -> 24000000 | L18: Catatan: Perlu penetapan kriteria penerima, dan crosscheck data karena dimungkinkan dobel anggaran
G20: Pandanlandung, 29 November 2025
A21: Pj. Kepala Desa Pandanlandung | G21: Pelaksana Kegiatan
A25: HARI SULISTIONO, S.AP | G25: MOH IKHSAN

Sheet SARPRAS POSYANDU
A1: RENCANA ANGGARAN BIAYA (RAB) | L1: Check Sum:
A2: PEMERINTAH DESA PANDANLANDUNG | L2: DDS | M2: =J13 -> 3700000
A3: TAHUN ANGGARAN 2026 | L3: PBH | M3: 0
A5: Bidang | C5: : | D5: PELAKSANAAN PEMBANGUNAN DESA
A6: Kegiatan | C6: : | D6: Pengadaan Sarana dan Prasarana Posyandu
A7: Waktu | C7: : | D7: 12 Bulan
A8: Output | C8: : | D8: Sarana Prasarana Posyandu
A10: KODE | B10: U R A I A N | G10: RINCIAN
G11: VOLUME | I11: HARGA SATUAN | J11: JUMLAH (Rp)
A12: 1 | B12: 2 | G12: 3 | I12: 4 | J12: 5
A13: 5 | B13: BELANJA | J13: =J15 -> 3700000
B14: Sarpras Posyandu
B15: Belanja Modal | J15: =J16 -> 3700000
C16: Belanja Modal Lainnya | J16: 3700000
C17: 01 | D17: Meja | E17: DDS | G17: 2 | H17: Bh | I17: 350000 | J17: =I17*G17 -> 700000
C18: 02 | D18: Kursi | E18: DDS | G18: 25 | H18: Bh | I18: 120000 | J18: =I18*G18 -> 3000000
B19: JUMLAH (Rp) | J19: =J13 -> 3700000
G21: Pandanlandung, 29 November 2025
A22: Pj. Kepala Desa Pandanlandung | G22: Pelaksana Kegiatan
A26: HARI SULISTIONO, S.AP | G26: MOH IKHSAN

Sheet POSYANDU
A1: RENCANA ANGGARAN BIAYA (RAB)
A2: PEMERINTAH DESA PANDANLANDUNG | L2: Check Sum:
A3: TAHUN ANGGARAN 2024 | L3: DDS | M3: =J13 -> 67284000
L4: PBH | M4: 0
A5: Bidang | C5: : | D5: PELAKSANAAN PEMBANGUNAN DESA
